Traceback (most recent call last):
  File "/home/chauvet/miniconda3/envs/basepy38/lib/python3.8/site-packages/jupyter_cache/executors/utils.py", line 51, in single_nb_execution
    executenb(
  File "/home/chauvet/miniconda3/envs/basepy38/lib/python3.8/site-packages/nbclient/client.py", line 1112, in execute
    return NotebookClient(nb=nb, resources=resources, km=km, **kwargs).execute()
  File "/home/chauvet/miniconda3/envs/basepy38/lib/python3.8/site-packages/nbclient/util.py", line 74, in wrapped
    return just_run(coro(*args, **kwargs))
  File "/home/chauvet/miniconda3/envs/basepy38/lib/python3.8/site-packages/nbclient/util.py", line 53, in just_run
    return loop.run_until_complete(coro)
  File "/home/chauvet/miniconda3/envs/basepy38/lib/python3.8/asyncio/base_events.py", line 616, in run_until_complete
    return future.result()
  File "/home/chauvet/miniconda3/envs/basepy38/lib/python3.8/site-packages/nbclient/client.py", line 553, in async_execute
    await self.async_execute_cell(
  File "/home/chauvet/miniconda3/envs/basepy38/lib/python3.8/site-packages/nbclient/client.py", line 857, in async_execute_cell
    self._check_raise_for_error(cell, exec_reply)
  File "/home/chauvet/miniconda3/envs/basepy38/lib/python3.8/site-packages/nbclient/client.py", line 760, in _check_raise_for_error
    raise CellExecutionError.from_cell_and_msg(cell, exec_reply_content)
nbclient.exceptions.CellExecutionError: An error occurred while executing the following cell:
------------------
data.aita.craft('granular',res=0.5)
------------------

[0;31m---------------------------------------------------------------------------[0m
[0;31mNameError[0m                                 Traceback (most recent call last)
[0;32m<ipython-input-6-9eb9ed08e866>[0m in [0;36m<module>[0;34m[0m
[0;32m----> 1[0;31m [0mdata[0m[0;34m.[0m[0maita[0m[0;34m.[0m[0mcraft[0m[0;34m([0m[0;34m'granular'[0m[0;34m,[0m[0mres[0m[0;34m=[0m[0;36m0.5[0m[0;34m)[0m[0;34m[0m[0;34m[0m[0m
[0m
[0;32m~/Documents/GitToolboxs/xarray_aita/xarrayaita/aita.py[0m in [0;36mcraft[0;34m(self, nameId, res)[0m
[1;32m     97[0m         [0;31m# Copy and compute mean grain[0m[0;34m[0m[0;34m[0m[0;34m[0m[0m
[1;32m     98[0m         [0mds[0m [0;34m=[0m [0mself[0m[0;34m.[0m[0m_obj[0m[0;34m.[0m[0mcopy[0m[0;34m([0m[0;34m)[0m[0;34m[0m[0;34m[0m[0m
[0;32m---> 99[0;31m         [0mds[0m[0;34m[[0m[0;34m'orientation_mg'[0m[0;34m][0m[0;34m=[0m[0mds[0m[0;34m.[0m[0maita[0m[0;34m.[0m[0mmean_grain[0m[0;34m([0m[0;34m)[0m[0;34m[0m[0;34m[0m[0m
[0m[1;32m    100[0m         [0;31m# Remove hole in grainId[0m[0;34m[0m[0;34m[0m[0;34m[0m[0m
[1;32m    101[0m         [0mnew_g[0m [0;34m=[0m [0mscipy[0m[0;34m.[0m[0mndimage[0m[0;34m.[0m[0mmaximum_filter[0m[0;34m([0m[0mnp[0m[0;34m.[0m[0marray[0m[0;34m([0m[0mds[0m[0;34m.[0m[0mgrainId[0m[0;34m)[0m[0;34m,[0m [0;36m3[0m[0;34m)[0m[0;34m[0m[0;34m[0m[0m

[0;32m~/Documents/GitToolboxs/xarray_aita/xarrayaita/aita.py[0m in [0;36mmean_grain[0;34m(self, dilate)[0m
[1;32m    183[0m             [0mmm[0m[0;34m=[0m[0mnp[0m[0;34m.[0m[0marray[0m[0;34m([0m[0mself[0m[0;34m.[0m[0m_obj[0m[0;34m.[0m[0mgrainId[0m[0;34m)[0m[0;34m==[0m[0mi[0m[0;34m[0m[0;34m[0m[0m
[1;32m    184[0m             [0;32mif[0m [0mdilate[0m[0;34m:[0m[0;34m[0m[0;34m[0m[0m
[0;32m--> 185[0;31m                 [0mmm[0m[0;34m=[0m[0mmorphology[0m[0;34m.[0m[0mbinary_dilation[0m[0;34m([0m[0mmm[0m[0;34m)[0m[0;34m[0m[0;34m[0m[0m
[0m[1;32m    186[0m [0;34m[0m[0m
[1;32m    187[0m [0;34m[0m[0m

[0;31mNameError[0m: name 'morphology' is not defined
NameError: name 'morphology' is not defined

