Traceback (most recent call last):
  File "/home/chauvet/miniconda3/envs/basepy38/lib/python3.8/site-packages/jupyter_cache/executors/utils.py", line 51, in single_nb_execution
    executenb(
  File "/home/chauvet/miniconda3/envs/basepy38/lib/python3.8/site-packages/nbclient/client.py", line 1112, in execute
    return NotebookClient(nb=nb, resources=resources, km=km, **kwargs).execute()
  File "/home/chauvet/miniconda3/envs/basepy38/lib/python3.8/site-packages/nbclient/util.py", line 74, in wrapped
    return just_run(coro(*args, **kwargs))
  File "/home/chauvet/miniconda3/envs/basepy38/lib/python3.8/site-packages/nbclient/util.py", line 53, in just_run
    return loop.run_until_complete(coro)
  File "/home/chauvet/miniconda3/envs/basepy38/lib/python3.8/asyncio/base_events.py", line 616, in run_until_complete
    return future.result()
  File "/home/chauvet/miniconda3/envs/basepy38/lib/python3.8/site-packages/nbclient/client.py", line 553, in async_execute
    await self.async_execute_cell(
  File "/home/chauvet/miniconda3/envs/basepy38/lib/python3.8/site-packages/nbclient/client.py", line 857, in async_execute_cell
    self._check_raise_for_error(cell, exec_reply)
  File "/home/chauvet/miniconda3/envs/basepy38/lib/python3.8/site-packages/nbclient/client.py", line 760, in _check_raise_for_error
    raise CellExecutionError.from_cell_and_msg(cell, exec_reply_content)
nbclient.exceptions.CellExecutionError: An error occurred while executing the following cell:
------------------
import numpy as np
import matplotlib.pyplot as plt
import matplotlib.cm as cm
import xarrayaita.loadData_aita as lda
import xarrayaita.aita as xa
import xarrayuvecs.uvecs as xu
import xarray as xr
------------------

[0;31m---------------------------------------------------------------------------[0m
[0;31mModuleNotFoundError[0m                       Traceback (most recent call last)
[0;32m<ipython-input-1-101c1b9d1584>[0m in [0;36m<module>[0;34m[0m
[1;32m      4[0m [0;32mimport[0m [0mxarrayaita[0m[0;34m.[0m[0mloadData_aita[0m [0;32mas[0m [0mlda[0m[0;34m[0m[0;34m[0m[0m
[1;32m      5[0m [0;32mimport[0m [0mxarrayaita[0m[0;34m.[0m[0maita[0m [0;32mas[0m [0mxa[0m[0;34m[0m[0;34m[0m[0m
[0;32m----> 6[0;31m [0;32mimport[0m [0mxarrayuvecs[0m[0;34m.[0m[0muvecs[0m [0;32mas[0m [0mxu[0m[0;34m[0m[0;34m[0m[0m
[0m[1;32m      7[0m [0;32mimport[0m [0mxarray[0m [0;32mas[0m [0mxr[0m[0;34m[0m[0;34m[0m[0m

[0;32m~/Documents/GitToolboxs/xarray_uvecs/xarrayuvecs/uvecs.py[0m in [0;36m<module>[0;34m[0m
[1;32m      2[0m [0mThis[0m [0;32mis[0m [0man[0m [0mobject[0m [0mto[0m [0mtake[0m [0mcare[0m [0mof[0m [0munit[0m [0mvector[0m[0;34m[0m[0;34m[0m[0m
[1;32m      3[0m '''
[0;32m----> 4[0;31m [0;32mimport[0m [0mxarray_uvecs[0m[0;34m.[0m[0muniform_dist[0m[0;34m[0m[0;34m[0m[0m
[0m[1;32m      5[0m [0;32mimport[0m [0mxarray_uvecs[0m[0;34m.[0m[0mlut2d[0m[0;34m[0m[0;34m[0m[0m
[1;32m      6[0m [0;34m[0m[0m

[0;31mModuleNotFoundError[0m: No module named 'xarray_uvecs'
ModuleNotFoundError: No module named 'xarray_uvecs'

